Workbook
Name AlevelPts: RESULTS!$AU$10:$AV$19
Name DivPTSOlevel: #REF!
Name Exams: #REF!
Name OLevelpts: #REF!

Sheet RESULTS
A1: ST. JUDE'S SECONDARY SCHOOL · F6 NECTA RESULTS · 2026 · 190 STUDENTS
D3: DIVISION | E3: I | F3: II | G3: III | H3: IV | I3: O | J3: ABS | K3: INC | L3: TOT | M3: KPI% | N3: GPA | O3: GPA GRADE | P3: SPA
D4: MALE | E4: =COUNTIFS(F6Results_2026[[Sex]:[Sex]],"M",F6Results_2026[[Div]:[Div]],"I") -> 12 | F4: =COUNTIFS(F6Results_2026[[Sex]:[Sex]],"M",F6Results_2026[[Div]:[Div]],"II") -> 29 | G4: =COUNTIFS(F6Results_2026[[Sex]:[Sex]],"M",F6Results_2026[[Div]:[Div]],"III") -> 37 | H4: =COUNTIFS(F6Results_2026[[Sex]:[Sex]],"M",F6Results_2026[[Div]:[Div]],"IV") -> 3 | I4: =COUNTIFS(F6Results_2026[[Sex]:[Sex]],"M",F6Results_2026[[Div]:[Div]],"O") -> 6 | J4: =COUNTIFS(F6Results_2026[[Sex]:[Sex]],"M",F6Results_2026[[Div]:[Div]],"ABS") -> 0 | K4: =COUNTIFS(F6Results_2026[[Sex]:[Sex]],"M",F6Results_2026[[Div]:[Div]],"INC") -> 0 | L4: =SUM(E4:K4) -> 87 | M4: {=SUM((E4:F4)/(SUM(E4:I4))*100)} -> 47.126437 | N4: =AL48 -> 2.2183908 | P4: =AVERAGEIFS(F6Results_2026[Points],F6Results_2026[[Sex]:[Sex]],"M") -> 13
D5: FEMALE | E5: =COUNTIFS(F6Results_2026[[Sex]:[Sex]],"F",F6Results_2026[[Div]:[Div]],"I") -> 26 | F5: =COUNTIFS(F6Results_2026[[Sex]:[Sex]],"F",F6Results_2026[[Div]:[Div]],"II") -> 36 | G5: =COUNTIFS(F6Results_2026[[Sex]:[Sex]],"F",F6Results_2026[[Div]:[Div]],"III") -> 34 | H5: =COUNTIFS(F6Results_2026[[Sex]:[Sex]],"F",F6Results_2026[[Div]:[Div]],"IV") -> 3 | I5: =COUNTIFS(F6Results_2026[[Sex]:[Sex]],"F",F6Results_2026[[Div]:[Div]],"O") -> 3 | J5: =COUNTIFS(F6Results_2026[[Sex]:[Sex]],"F",F6Results_2026[[Div]:[Div]],"ABS") -> 0 | K5: =COUNTIFS(F6Results_2026[[Sex]:[Sex]],"F",F6Results_2026[[Div]:[Div]],"INC") -> 0 | L5: =SUM(E5:K5) -> 102 | M5: {=SUM((E5:F5)/(SUM(E5:I5))*100)} -> 60.784314 | N5: =AM48 -> 2.0784314 | P5: =AVERAGEIFS(F6Results_2026[Points],F6Results_2026[[Sex]:[Sex]],"F") -> 11.77451
D6: SCHOOL | E6: =SUM(E4:E5) -> 38 | F6: =SUM(F4:F5) -> 65 | G6: =SUM(G4:G5) -> 71 | H6: =SUM(H4:H5) -> 6 | I6: =SUM(I4:I5) -> 9 | J6: =SUM(J4:J5) -> 0 | K6: =SUM(K4:K5) -> 0 | L6: =SUM(L4:L5) -> 189 | M6: {=SUM((E6:F6)/(SUM(E6:I6))*100)} -> 54.497354 | N6: =AK49 -> 3.2632275 | P6: =IFERROR(AVERAGE(F6Results_2026[Points]),"") -> 12.338624
A8: Students Details | G8: F6 Results | K8: Subjects and Aggr Points | AA8: F4 CSEE 2023 | AF8: F2 CSEE 2021
A9: Cand_No | B9: Year | C9: PREM_NO | D9: Full_Name | E9: Comb | F9: Group | G9: Sex | H9: Points | I9: Div | J9: From | K9: Gs | L9: Bam | M9: Hist | N9: Geo | O9: Kisw | P9: Engl | Q9: Phy | R9: Chem | S9: Biol | T9: Agr | U9: Adv_Math | V9: Comp_Sci | W9: Econ | X9: Comm | Y9: Acco | Z9: Aggr_Pts | AA9: F4_Pts | AB9: F4_Div | AC9: Csee_A's | AD9: Comb_Adm_Pts | AE9: Comb_Qualification | AF9: FTNA_Pts | AG9: FTNA_Div | AH9: FTNA_A's
A10: S4459/0550 | B10: 2026 | C10: 20130180105 | D10: JAMES BARAKA SIKAWA | E10: HGK | F10: Arts | G10: M | H10: {=_xlfn.LET( _xlpm.g, F6Results_2026[[#This Row],[Hist]:[Acco]], _xlpm.pts, _xlfn.MAP(_xlpm.g, _xlfn.LAMBDA(_xlpm.x, IFERROR(VLOOKUP(_xlpm.x, AlevelPts, 2, FALSE), ""))), _xlpm.validPts, _xlfn._xlws.FILTER(_xlpm.pts, ISNUMBER(_xlpm.pts)), _xlpm.allBlank, SUM(--(_xlpm.g=""))=COLUMNS(_xlpm.g), IF( _xlpm.allBlank, "ABS", IFERROR(SUM(_xlpm.validPts), "") ) )} -> 7 | I10: =VLOOKUP(H10,$AO$11:$AP$17,2,TRUE) -> I | J10: GVT | K10: D | M10: C | N10: C | O10: A | Z10: {=SUM(IF(K10:Y10="A",1,0), IF(K10:Y10="B",2,0), IF(K10:Y10="C",3,0), IF(K10:Y10="D",4,0), IF(K10:Y10="E",5,0), IF(K10:Y10="S",6,0), IF(K10:Y10="F",7,0))} -> 11 | AA10: =_xlfn.XLOOKUP(F6Results_2026[[#This Row],[Full_Name]],tblF42023[FULL_NAME],tblF42023[POINTS],"",0,1) | AB10: =_xlfn.XLOOKUP(F6Results_2026[[#This Row],[Full_Name]],tblF42023[FULL_NAME],tblF42023[DIVISION],"",0,1) | AC10: =_xlfn.XLOOKUP(F6Results_2026[[#This Row],[Full_Name]],tblF42023[FULL_NAME],tblF42023[POINTS],"",0,1) | AD10: =IFERROR( INDEX(tblF42023[[HKL]:[CBA]], MATCH(F6Results_2026[[#This Row],[Full_Name]], tblF42023[FULL_NAME], 0), MATCH(F6Results_2026[[#This Row],[Comb]], tblF42023[[#Headers],[HKL]:[CBA]], 0) ), "" ) | AE10: =IFERROR( INDEX(tblF42023[], MATCH(F6Results_2026[[#This Row],[Full_Name]], tblF42023[FULL_NAME], 0), MATCH(F6Results_2026[[#This Row],[Comb]] & "_Q", tblF42023[#Headers], 0) ), "" ) | AF10: =_xlfn.XLOOKUP(F6Results_2026[[#This Row],[Full_Name]],tblF22021[FULL_NAME],tblF22021[POINTS],"",0,1) | AG10: =_xlfn.XLOOKUP(F6Results_2026[[#This Row],[Full_Name]],tblF42023[FULL_NAME],tblF42023[DIVISION],"",0,1) | AH10: =_xlfn.XLOOKUP(F6Results_2026[[#This Row],[Full_Name]],tblF42023[FULL_NAME],tblF42023[TOTAL A''S],"",0,1) | AO10: Value | AP10: Grade | AQ10: Value | AR10: Grade | AS10: - | AT10: - | AU10: - | AV10: -
A11: S4459/0545 | B11: 2026 | C11: 20130180844 | D11: SHARON EDWARD MNYAMPANDA | E11: HGK | F11: Arts | G11: F | H11: {=_xlfn.LET( _xlpm.g, F6Results_2026[[#This Row],[Hist]:[Acco]], _xlpm.pts, _xlfn.MAP(_xlpm.g, _xlfn.LAMBDA(_xlpm.x, IFERROR(VLOOKUP(_xlpm.x, AlevelPts, 2, FALSE), ""))), _xlpm.validPts, _xlfn._xlws.FILTER(_xlpm.pts, ISNUMBER(_xlpm.pts)), _xlpm.allBlank, SUM(--(_xlpm.g=""))=COLUMNS(_xlpm.g), IF( _xlpm.allBlank, "ABS", IFERROR(SUM(_xlpm.validPts), "") ) )} -> 8 | I11: =VLOOKUP(H11,$AO$11:$AP$17,2,TRUE) -> I | J11: GVT | K11: E | M11: C | N11: D | O11: A | Z11: {=SUM(IF(K11:Y11="A",1,0), IF(K11:Y11="B",2,0), IF(K11:Y11="C",3,0), IF(K11:Y11="D",4,0), IF(K11:Y11="E",5,0), IF(K11:Y11="S",6,0), IF(K11:Y11="F",7,0))} -> 13 | AA11: =_xlfn.XLOOKUP(F6Results_2026[[#This Row],[Full_Name]],tblF42023[FULL_NAME],tblF42023[POINTS],"",0,1) | AB11: =_xlfn.XLOOKUP(F6Results_2026[[#This Row],[Full_Name]],tblF42023[FULL_NAME],tblF42023[DIVISION],"",0,1) | AC11: =_xlfn.XLOOKUP(F6Results_2026[[#This Row],[Full_Name]],tblF42023[FULL_NAME],tblF42023[POINTS],"",0,1) | AD11: =IFERROR( INDEX(tblF42023[[HKL]:[CBA]], MATCH(F6Results_2026[[#This Row],[Full_Name]], tblF42023[FULL_NAME], 0), MATCH(F6Results_2026[[#This Row],[Comb]], tblF42023[[#Headers],[HKL]:[CBA]], 0) ), "" ) | AE11: =IFERROR( INDEX(tblF42023[], MATCH(F6Results_2026[[#This Row],[Full_Name]], tblF42023[FULL_NAME], 0), MATCH(F6Results_2026[[#This Row],[Comb]] & "_Q", tblF42023[#Headers], 0) ), "" ) | AF11: =_xlfn.XLOOKUP(F6Results_2026[[#This Row],[Full_Name]],tblF22021[FULL_NAME],tblF22021[POINTS],"",0,1) | AG11: =_xlfn.XLOOKUP(F6Results_2026[[#This Row],[Full_Name]],tblF42023[FULL_NAME],tblF42023[DIVISION],"",0,1) | AH11: =_xlfn.XLOOKUP(F6Results_2026[[#This Row],[Full_Name]],tblF42023[FULL_NAME],tblF42023[TOTAL A''S],"",0,1) | AO11: ABS | AP11: ABS | AQ11: INC | AR11: INC | AS11: INC | AT11: INC | AU11: INC | AV11: INC
A12: S4459/0656 | B12: 2026 | C12: 20130189255 | D12: ANNA PRAYAGOD MBISE | E12: ECA | F12: Business | G12: F | H12: {=_xlfn.LET( _xlpm.g, F6Results_2026[[#This Row],[Hist]:[Acco]], _xlpm.pts, _xlfn.MAP(_xlpm.g, _xlfn.LAMBDA(_xlpm.x, IFERROR(VLOOKUP(_xlpm.x, AlevelPts, 2, FALSE), ""))), _xlpm.validPts, _xlfn._xlws.FILTER(_xlpm.pts, ISNUMBER(_xlpm.pts)), _xlpm.allBlank, SUM(--(_xlpm.g=""))=COLUMNS(_xlpm.g), IF( _xlpm.allBlank, "ABS", IFERROR(SUM(_xlpm.validPts), "") ) )} -> 21 | I12: =VLOOKUP(H12,$AO$11:$AP$17,2,TRUE) -> O | J12: ST.JUDE | K12: E | L12: A | W12: F | X12: F | Y12: F | Z12: {=SUM(IF(K12:Y12="A",1,0), IF(K12:Y12="B",2,0), IF(K12:Y12="C",3,0), IF(K12:Y12="D",4,0), IF(K12:Y12="E",5,0), IF(K12:Y12="S",6,0), IF(K12:Y12="F",7,0))} -> 27 | AA12: =_xlfn.XLOOKUP(F6Results_2026[[#This Row],[Full_Name]],tblF42023[FULL_NAME],tblF42023[POINTS],"",0,1) | AB12: =_xlfn.XLOOKUP(F6Results_2026[[#This Row],[Full_Name]],tblF42023[FULL_NAME],tblF42023[DIVISION],"",0,1) | AC12: =_xlfn.XLOOKUP(F6Results_2026[[#This Row],[Full_Name]],tblF42023[FULL_NAME],tblF42023[POINTS],"",0,1) | AD12: =IFERROR( INDEX(tblF42023[[HKL]:[CBA]], MATCH(F6Results_2026[[#This Row],[Full_Name]], tblF42023[FULL_NAME], 0), MATCH(F6Results_2026[[#This Row],[Comb]], tblF42023[[#Headers],[HKL]:[CBA]], 0) ), "" ) | AE12: =IFERROR( INDEX(tblF42023[], MATCH(F6Results_2026[[#This Row],[Full_Name]], tblF42023[FULL_NAME], 0), MATCH(F6Results_2026[[#This Row],[Comb]] & "_Q", tblF42023[#Headers], 0) ), "" ) | AF12: =_xlfn.XLOOKUP(F6Results_2026[[#This Row],[Full_Name]],tblF22021[FULL_NAME],tblF22021[POINTS],"",0,1) -> 7 | AG12: =_xlfn.XLOOKUP(F6Results_2026[[#This Row],[Full_Name]],tblF42023[FULL_NAME],tblF42023[DIVISION],"",0,1) | AH12: =_xlfn.XLOOKUP(F6Results_2026[[#This Row],[Full_Name]],tblF42023[FULL_NAME],tblF42023[TOTAL A''S],"",0,1) | AO12: INC | AP12: INC | AQ12: - | AR12: - | AS12: IINC | AT12: INC | AU12: ABS | AV12: ABS
A13: S4459/0617 | B13: 2026 | C13: 20130191313 | D13: EDITHA TEREVAEL KAAYA | E13: PCB | F13: Science | G13: F | H13: {=_xlfn.LET( _xlpm.g, F6Results_2026[[#This Row],[Hist]:[Acco]], _xlpm.pts, _xlfn.MAP(_xlpm.g, _xlfn.LAMBDA(_xlpm.x, IFERROR(VLOOKUP(_xlpm.x, AlevelPts, 2, FALSE), ""))), _xlpm.validPts, _xlfn._xlws.FILTER(_xlpm.pts, ISNUMBER(_xlpm.pts)), _xlpm.allBlank, SUM(--(_xlpm.g=""))=COLUMNS(_xlpm.g), IF( _xlpm.allBlank, "ABS", IFERROR(SUM(_xlpm.validPts), "") ) )} -> 13 | I13: =VLOOKUP(H13,$AO$11:$AP$17,2,TRUE) -> III | J13: GVT | K13: D | L13: B | Q13: C | R13: C | S13: F | Z13: {=SUM(IF(K13:Y13="A",1,0), IF(K13:Y13="B",2,0), IF(K13:Y13="C",3,0), IF(K13:Y13="D",4,0), IF(K13:Y13="E",5,0), IF(K13:Y13="S",6,0), IF(K13:Y13="F",7,0))} -> 19 | AA13: =_xlfn.XLOOKUP(F6Results_2026[[#This Row],[Full_Name]],tblF42023[FULL_NAME],tblF42023[POINTS],"",0,1) | AB13: =_xlfn.XLOOKUP(F6Results_2026[[#This Row],[Full_Name]],tblF42023[FULL_NAME],tblF42023[DIVISION],"",0,1) | AC13: =_xlfn.XLOOKUP(F6Results_2026[[#This Row],[Full_Name]],tblF42023[FULL_NAME],tblF42023[POINTS],"",0,1) | AD13: =IFERROR( INDEX(tblF42023[[HKL]:[CBA]], MATCH(F6Results_2026[[#This Row],[Full_Name]], tblF42023[FULL_NAME], 0), MATCH(F6Results_2026[[#This Row],[Comb]], tblF42023[[#Headers],[HKL]:[CBA]], 0) ), "" ) | AE13: =IFERROR( INDEX(tblF42023[], MATCH(F6Results_2026[[#This Row],[Full_Name]], tblF42023[FULL_NAME], 0), MATCH(F6Results_2026[[#This Row],[Comb]] & "_Q", tblF42023[#Headers], 0) ), "" ) | AF13: =_xlfn.XLOOKUP(F6Results_2026[[#This Row],[Full_Name]],tblF22021[FULL_NAME],tblF22021[POINTS],"",0,1) | AG13: =_xlfn.XLOOKUP(F6Results_2026[[#This Row],[Full_Name]],tblF42023[FULL_NAME],tblF42023[DIVISION],"",0,1) | AH13: =_xlfn.XLOOKUP(F6Results_2026[[#This Row],[Full_Name]],tblF42023[FULL_NAME],tblF42023[TOTAL A''S],"",0,1) | AO13: 0 | AP13: I | AQ13: 0 | AR13: F | AS13: F | AT13: 5 | AU13: F | AV13: 7
A14: S4459/0544 | B14: 2026 | C14: 20130210418 | D14: SCOLA PETER NNKO | E14: HGK | F14: Arts | G14: F | H14: {=_xlfn.LET( _xlpm.g, F6Results_2026[[#This Row],[Hist]:[Acco]], _xlpm.pts, _xlfn.MAP(_xlpm.g, _xlfn.LAMBDA(_xlpm.x, IFERROR(VLOOKUP(_xlpm.x, AlevelPts, 2, FALSE), ""))), _xlpm.validPts, _xlfn._xlws.FILTER(_xlpm.pts, ISNUMBER(_xlpm.pts)), _xlpm.allBlank, SUM(--(_xlpm.g=""))=COLUMNS(_xlpm.g), IF( _xlpm.allBlank, "ABS", IFERROR(SUM(_xlpm.validPts), "") ) )} -> 7 | I14: =VLOOKUP(H14,$AO$11:$AP$17,2,TRUE) -> I | J14: ST.JUDE | K14: D | M14: C | N14: C | O14: A | Z14: {=SUM(IF(K14:Y14="A",1,0), IF(K14:Y14="B",2,0), IF(K14:Y14="C",3,0), IF(K14:Y14="D",4,0), IF(K14:Y14="E",5,0), IF(K14:Y14="S",6,0), IF(K14:Y14="F",7,0))} -> 11 | AA14: =_xlfn.XLOOKUP(F6Results_2026[[#This Row],[Full_Name]],tblF42023[FULL_NAME],tblF42023[POINTS],"",0,1) -> 13 | AB14: =_xlfn.XLOOKUP(F6Results_2026[[#This Row],[Full_Name]],tblF42023[FULL_NAME],tblF42023[DIVISION],"",0,1) -> I | AC14: =_xlfn.XLOOKUP(F6Results_2026[[#This Row],[Full_Name]],tblF42023[FULL_NAME],tblF42023[POINTS],"",0,1) -> 13 | AD14: =IFERROR( INDEX(tblF42023[[HKL]:[CBA]], MATCH(F6Results_2026[[#This Row],[Full_Name]], tblF42023[FULL_NAME], 0), MATCH(F6Results_2026[[#This Row],[Comb]], tblF42023[[#Headers],[HKL]:[CBA]], 0) ), "" ) -> 6 | AE14: =IFERROR( INDEX(tblF42023[], MATCH(F6Results_2026[[#This Row],[Full_Name]], tblF42023[FULL_NAME], 0), MATCH(F6Results_2026[[#This Row],[Comb]] & "_Q", tblF42023[#Headers], 0) ), "" ) -> Y | AF14: =_xlfn.XLOOKUP(F6Results_2026[[#This Row],[Full_Name]],tblF22021[FULL_NAME],tblF22021[POINTS],"",0,1) -> 7 | AG14: =_xlfn.XLOOKUP(F6Results_2026[[#This Row],[Full_Name]],tblF42023[FULL_NAME],tblF42023[DIVISION],"",0,1) -> I | AH14: =_xlfn.XLOOKUP(F6Results_2026[[#This Row],[Full_Name]],tblF42023[FULL_NAME],tblF42023[TOTAL A''S],"",0,1) -> 2 | AO14: 10 | AP14: II | AQ14: 34.5 | AR14: S | AS14: D | AT14: 4 | AU14: S | AV14: 6
A15: S4459/0633 | B15: 2026 | C15: 20130232282 | D15: BARAKA ELIYA TIPPE | E15: PCB | F15: Science | G15: M | H15: {=_xlfn.LET( _xlpm.g, F6Results_2026[[#This Row],[Hist]:[Acco]], _xlpm.pts, _xlfn.MAP(_xlpm.g, _xlfn.LAMBDA(_xlpm.x, IFERROR(VLOOKUP(_xlpm.x, AlevelPts, 2, FALSE), ""))), _xlpm.validPts, _xlfn._xlws.FILTER(_xlpm.pts, ISNUMBER(_xlpm.pts)), _xlpm.allBlank, SUM(--(_xlpm.g=""))=COLUMNS(_xlpm.g), IF( _xlpm.allBlank, "ABS", IFERROR(SUM(_xlpm.validPts), "") ) )} -> 17 | I15: =VLOOKUP(H15,$AO$11:$AP$17,2,TRUE) -> III | J15: GVT | K15: S | L15: D | Q15: C | R15: F | S15: F | Z15: {=SUM(IF(K15:Y15="A",1,0), IF(K15:Y15="B",2,0), IF(K15:Y15="C",3,0), IF(K15:Y15="D",4,0), IF(K15:Y15="E",5,0), IF(K15:Y15="S",6,0), IF(K15:Y15="F",7,0))} -> 27 | AA15: =_xlfn.XLOOKUP(F6Results_2026[[#This Row],[Full_Name]],tblF42023[FULL_NAME],tblF42023[POINTS],"",0,1) | AB15: =_xlfn.XLOOKUP(F6Results_2026[[#This Row],[Full_Name]],tblF42023[FULL_NAME],tblF42023[DIVISION],"",0,1) | AC15: =_xlfn.XLOOKUP(F6Results_2026[[#This Row],[Full_Name]],tblF42023[FULL_NAME],tblF42023[POINTS],"",0,1) | AD15: =IFERROR( INDEX(tblF42023[[HKL]:[CBA]], MATCH(F6Results_2026[[#This Row],[Full_Name]], tblF42023[FULL_NAME], 0), MATCH(F6Results_2026[[#This Row],[Comb]], tblF42023[[#Headers],[HKL]:[CBA]], 0) ), "" ) | AE15: =IFERROR( INDEX(tblF42023[], MATCH(F6Results_2026[[#This Row],[Full_Name]], tblF42023[FULL_NAME], 0), MATCH(F6Results_2026[[#This Row],[Comb]] & "_Q", tblF42023[#Headers], 0) ), "" ) | AF15: =_xlfn.XLOOKUP(F6Results_2026[[#This Row],[Full_Name]],tblF22021[FULL_NAME],tblF22021[POINTS],"",0,1) | AG15: =_xlfn.XLOOKUP(F6Results_2026[[#This Row],[Full_Name]],tblF42023[FULL_NAME],tblF42023[DIVISION],"",0,1) | AH15: =_xlfn.XLOOKUP(F6Results_2026[[#This Row],[Full_Name]],tblF42023[FULL_NAME],tblF42023[TOTAL A''S],"",0,1) | AO15: 13 | AP15: III | AQ15: 39.5 | AR15: E | AS15: C | AT15: 3 | AU15: E | AV15: 5
A16: S4459/0551 | B16: 2026 | C16: 20130238026 | D16: JOSEPH JOEL DANIEL | E16: HGK | F16: Arts | G16: M | H16: {=_xlfn.LET( _xlpm.g, F6Results_2026[[#This Row],[Hist]:[Acco]], _xlpm.pts, _xlfn.MAP(_xlpm.g, _xlfn.LAMBDA(_xlpm.x, IFERROR(VLOOKUP(_xlpm.x, AlevelPts, 2, FALSE), ""))), _xlpm.validPts, _xlfn._xlws.FILTER(_xlpm.pts, ISNUMBER(_xlpm.pts)), _xlpm.allBlank, SUM(--(_xlpm.g=""))=COLUMNS(_xlpm.g), IF( _xlpm.allBlank, "ABS", IFERROR(SUM(_xlpm.validPts), "") ) )} -> 7 | I16: =VLOOKUP(H16,$AO$11:$AP$17,2,TRUE) -> I | J16: GVT | K16: D | M16: C | N16: C | O16: A | Z16: {=SUM(IF(K16:Y16="A",1,0), IF(K16:Y16="B",2,0), IF(K16:Y16="C",3,0), IF(K16:Y16="D",4,0), IF(K16:Y16="E",5,0), IF(K16:Y16="S",6,0), IF(K16:Y16="F",7,0))} -> 11 | AA16: =_xlfn.XLOOKUP(F6Results_2026[[#This Row],[Full_Name]],tblF42023[FULL_NAME],tblF42023[POINTS],"",0,1) | AB16: =_xlfn.XLOOKUP(F6Results_2026[[#This Row],[Full_Name]],tblF42023[FULL_NAME],tblF42023[DIVISION],"",0,1) | AC16: =_xlfn.XLOOKUP(F6Results_2026[[#This Row],[Full_Name]],tblF42023[FULL_NAME],tblF42023[POINTS],"",0,1) | AD16: =IFERROR( INDEX(tblF42023[[HKL]:[CBA]], MATCH(F6Results_2026[[#This Row],[Full_Name]], tblF42023[FULL_NAME], 0), MATCH(F6Results_2026[[#This Row],[Comb]], tblF42023[[#Headers],[HKL]:[CBA]], 0) ), "" ) | AE16: =IFERROR( INDEX(tblF42023[], MATCH(F6Results_2026[[#This Row],[Full_Name]], tblF42023[FULL_NAME], 0), MATCH(F6Results_2026[[#This Row],[Comb]] & "_Q", tblF42023[#Headers], 0) ), "" ) | AF16: =_xlfn.XLOOKUP(F6Results_2026[[#This Row],[Full_Name]],tblF22021[FULL_NAME],tblF22021[POINTS],"",0,1) | AG16: =_xlfn.XLOOKUP(F6Results_2026[[#This Row],[Full_Name]],tblF42023[FULL_NAME],tblF42023[DIVISION],"",0,1) | AH16: =_xlfn.XLOOKUP(F6Results_2026[[#This Row],[Full_Name]],tblF42023[FULL_NAME],tblF42023[TOTAL A''S],"",0,1) | AO16: 18 | AP16: IV | AQ16: 49.5 | AR16: D | AS16: B | AT16: 2 | AU16: D | AV16: 4
A17: S4459/0521 | B17: 2026 | C17: 20130238559 | D17: ABUBAKARI KIBWANA MNGODO | E17: HGL | F17: Arts | G17: M | H17: {=_xlfn.LET( _xlpm.g, F6Results_2026[[#This Row],[Hist]:[Acco]], _xlpm.pts, _xlfn.MAP(_xlpm.g, _xlfn.LAMBDA(_xlpm.x, IFERROR(VLOOKUP(_xlpm.x, AlevelPts, 2, FALSE), ""))), _xlpm.validPts, _xlfn._xlws.FILTER(_xlpm.pts, ISNUMBER(_xlpm.pts)), _xlpm.allBlank, SUM(--(_xlpm.g=""))=COLUMNS(_xlpm.g), IF( _xlpm.allBlank, "ABS", IFERROR(SUM(_xlpm.validPts), "") ) )} -> 11 | I17: =VLOOKUP(H17,$AO$11:$AP$17,2,TRUE) -> II | J17: ST.JUDE | K17: F | M17: D | N17: E | P17: B | Z17: {=SUM(IF(K17:Y17="A",1,0), IF(K17:Y17="B",2,0), IF(K17:Y17="C",3,0), IF(K17:Y17="D",4,0), IF(K17:Y17="E",5,0), IF(K17:Y17="S",6,0), IF(K17:Y17="F",7,0))} -> 18 | AA17: =_xlfn.XLOOKUP(F6Results_2026[[#This Row],[Full_Name]],tblF42023[FULL_NAME],tblF42023[POINTS],"",0,1) -> 15 | AB17: =_xlfn.XLOOKUP(F6Results_2026[[#This Row],[Full_Name]],tblF42023[FULL_NAME],tblF42023[DIVISION],"",0,1) -> I | AC17: =_xlfn.XLOOKUP(F6Results_2026[[#This Row],[Full_Name]],tblF42023[FULL_NAME],tblF42023[POINTS],"",0,1) -> 15 | AD17: =IFERROR( INDEX(tblF42023[[HKL]:[CBA]], MATCH(F6Results_2026[[#This Row],[Full_Name]], tblF42023[FULL_NAME], 0), MATCH(F6Results_2026[[#This Row],[Comb]], tblF42023[[#Headers],[HKL]:[CBA]], 0) ), "" ) -> 6 | AE17: =IFERROR( INDEX(tblF42023[], MATCH(F6Results_2026[[#This Row],[Full_Name]], tblF42023[FULL_NAME], 0), MATCH(F6Results_2026[[#This Row],[Comb]] & "_Q", tblF42023[#Headers], 0) ), "" ) -> Y | AF17: =_xlfn.XLOOKUP(F6Results_2026[[#This Row],[Full_Name]],tblF22021[FULL_NAME],tblF22021[POINTS],"",0,1) -> 8 | AG17: =_xlfn.XLOOKUP(F6Results_2026[[#This Row],[Full_Name]],tblF42023[FULL_NAME],tblF42023[DIVISION],"",0,1) -> I | AH17: =_xlfn.XLOOKUP(F6Results_2026[[#This Row],[Full_Name]],tblF42023[FULL_NAME],tblF42023[TOTAL A''S],"",0,1) -> 1 | AO17: 20 | AP17: O | AQ17: 59.5 | AR17: C | AS17: A | AT17: 1 | AU17: C | AV17: 3
A18: S4459/0586 | B18: 2026 | C18: 20130238684 | D18: LUCIANA SAULI LESSION | E18: PCM | F18: Science | G18: F | H18: {=_xlfn.LET( _xlpm.g, F6Results_2026[[#This Row],[Hist]:[Acco]], _xlpm.pts, _xlfn.MAP(_xlpm.g, _xlfn.LAMBDA(_xlpm.x, IFERROR(VLOOKUP(_xlpm.x, AlevelPts, 2, FALSE), ""))), _xlpm.validPts, _xlfn._xlws.FILTER(_xlpm.pts, ISNUMBER(_xlpm.pts)), _xlpm.allBlank, SUM(--(_xlpm.g=""))=COLUMNS(_xlpm.g), IF( _xlpm.allBlank, "ABS", IFERROR(SUM(_xlpm.validPts), "") ) )} -> 11 | I18: =VLOOKUP(H18,$AO$11:$AP$17,2,TRUE) -> II | J18: ST.JUDE | K18: S | Q18: C | R18: C | U18: E | Z18: {=SUM(IF(K18:Y18="A",1,0), IF(K18:Y18="B",2,0), IF(K18:Y18="C",3,0), IF(K18:Y18="D",4,0), IF(K18:Y18="E",5,0), IF(K18:Y18="S",6,0), IF(K18:Y18="F",7,0))} -> 17 | AA18: =_xlfn.XLOOKUP(F6Results_2026[[#This Row],[Full_Name]],tblF42023[FULL_NAME],tblF42023[POINTS],"",0,1) -> 7 | AB18: =_xlfn.XLOOKUP(F6Results_2026[[#This Row],[Full_Name]],tblF42023[FULL_NAME],tblF42023[DIVISION],"",0,1) -> I | AC18: =_xlfn.XLOOKUP(F6Results_2026[[#This Row],[Full_Name]],tblF42023[FULL_NAME],tblF42023[POINTS],"",0,1) -> 7 | AD18: =IFERROR( INDEX(tblF42023[[HKL]:[CBA]], MATCH(F6Results_2026[[#This Row],[Full_Name]], tblF42023[FULL_NAME], 0), MATCH(F6Results_2026[[#This Row],[Comb]], tblF42023[[#Headers],[HKL]:[CBA]], 0) ), "" ) -> 5 | AE18: =IFERROR( INDEX(tblF42023[], MATCH(F6Results_2026[[#This Row],[Full_Name]], tblF42023[FULL_NAME], 0), MATCH(F6Results_2026[[#This Row],[Comb]] & "_Q", tblF42023[#Headers], 0) ), "" ) -> Y | AF18: =_xlfn.XLOOKUP(F6Results_2026[[#This Row],[Full_Name]],tblF22021[FULL_NAME],tblF22021[POINTS],"",0,1) -> 7 | AG18: =_xlfn.XLOOKUP(F6Results_2026[[#This Row],[Full_Name]],tblF42023[FULL_NAME],tblF42023[DIVISION],"",0,1) -> I | AH18: =_xlfn.XLOOKUP(F6Results_2026[[#This Row],[Full_Name]],tblF42023[FULL_NAME],tblF42023[TOTAL A''S],"",0,1) -> 9 | AU18: B | AV18: 2
A19: S4459/0669 | B19: 2026 | C19: 20130239051 | D19: FILMINA BOMBO NADE | E19: CBA | F19: Science | G19: F | H19: {=_xlfn.LET( _xlpm.g, F6Results_2026[[#This Row],[Hist]:[Acco]], _xlpm.pts, _xlfn.MAP(_xlpm.g, _xlfn.LAMBDA(_xlpm.x, IFERROR(VLOOKUP(_xlpm.x, AlevelPts, 2, FALSE), ""))), _xlpm.validPts, _xlfn._xlws.FILTER(_xlpm.pts, ISNUMBER(_xlpm.pts)), _xlpm.allBlank, SUM(--(_xlpm.g=""))=COLUMNS(_xlpm.g), IF( _xlpm.allBlank, "ABS", IFERROR(SUM(_xlpm.validPts), "") ) )} -> 10 | I19: =VLOOKUP(H19,$AO$11:$AP$17,2,TRUE) -> II | J19: GVT | K19: E | L19: F | R19: D | S19: C | T19: C | AA19: =_xlfn.XLOOKUP(F6Results_2026[[#This Row],[Full_Name]],tblF42023[FULL_NAME],tblF42023[POINTS],"",0,1) | AB19: =_xlfn.XLOOKUP(F6Results_2026[[#This Row],[Full_Name]],tblF42023[FULL_NAME],tblF42023[DIVISION],"",0,1) | AC19: =_xlfn.XLOOKUP(F6Results_2026[[#This Row],[Full_Name]],tblF42023[FULL_NAME],tblF42023[POINTS],"",0,1) | AD19: =IFERROR( INDEX(tblF42023[[HKL]:[CBA]], MATCH(F6Results_2026[[#This Row],[Full_Name]], tblF42023[FULL_NAME], 0), MATCH(F6Results_2026[[#This Row],[Comb]], tblF42023[[#Headers],[HKL]:[CBA]], 0) ), "" ) | AE19: =IFERROR( INDEX(tblF42023[], MATCH(F6Results_2026[[#This Row],[Full_Name]], tblF42023[FULL_NAME], 0), MATCH(F6Results_2026[[#This Row],[Comb]] & "_Q", tblF42023[#Headers], 0) ), "" ) | AF19: =_xlfn.XLOOKUP(F6Results_2026[[#This Row],[Full_Name]],tblF22021[FULL_NAME],tblF22021[POINTS],"",0,1) | AG19: =_xlfn.XLOOKUP(F6Results_2026[[#This Row],[Full_Name]],tblF42023[FULL_NAME],tblF42023[DIVISION],"",0,1) | AH19: =_xlfn.XLOOKUP(F6Results_2026[[#This Row],[Full_Name]],tblF42023[FULL_NAME],tblF42023[TOTAL A''S],"",0,1) | AU19: A | AV19: 1
A20: S4459/0602 | B20: 2026 | C20: 20130239312 | D20: JORDAN ERICK KIVUYO | E20: PCM | F20: Science | G20: M | H20: {=_xlfn.LET( _xlpm.g, F6Results_2026[[#This Row],[Hist]:[Acco]], _xlpm.pts, _xlfn.MAP(_xlpm.g, _xlfn.LAMBDA(_xlpm.x, IFERROR(VLOOKUP(_xlpm.x, AlevelPts, 2, FALSE), ""))), _xlpm.validPts, _xlfn._xlws.FILTER(_xlpm.pts, ISNUMBER(_xlpm.pts)), _xlpm.allBlank, SUM(--(_xlpm.g=""))=COLUMNS(_xlpm.g), IF( _xlpm.allBlank, "ABS", IFERROR(SUM(_xlpm.validPts), "") ) )} -> 11 | I20: =VLOOKUP(H20,$AO$11:$AP$17,2,TRUE) -> II | J20: GVT | K20: E | Q20: D | R20: C | U20: D | Z20: {=SUM(IF(K20:Y20="A",1,0), IF(K20:Y20="B",2,0), IF(K20:Y20="C",3,0), IF(K20:Y20="D",4,0), IF(K20:Y20="E",5,0), IF(K20:Y20="S",6,0), IF(K20:Y20="F",7,0))} -> 16 | AA20: =_xlfn.XLOOKUP(F6Results_2026[[#This Row],[Full_Name]],tblF42023[FULL_NAME],tblF42023[POINTS],"",0,1) | AB20: =_xlfn.XLOOKUP(F6Results_2026[[#This Row],[Full_Name]],tblF42023[FULL_NAME],tblF42023[DIVISION],"",0,1) | AC20: =_xlfn.XLOOKUP(F6Results_2026[[#This Row],[Full_Name]],tblF42023[FULL_NAME],tblF42023[POINTS],"",0,1) | AD20: =IFERROR( INDEX(tblF42023[[HKL]:[CBA]], MATCH(F6Results_2026[[#This Row],[Full_Name]], tblF42023[FULL_NAME], 0), MATCH(F6Results_2026[[#This Row],[Comb]], tblF42023[[#Headers],[HKL]:[CBA]], 0) ), "" ) | AE20: =IFERROR( INDEX(tblF42023[], MATCH(F6Results_2026[[#This Row],[Full_Name]], tblF42023[FULL_NAME], 0), MATCH(F6Results_2026[[#This Row],[Comb]] & "_Q", tblF42023[#Headers], 0) ), "" ) | AF20: =_xlfn.XLOOKUP(F6Results_2026[[#This Row],[Full_Name]],tblF22021[FULL_NAME],tblF22021[POINTS],"",0,1) | AG20: =_xlfn.XLOOKUP(F6Results_2026[[#This Row],[Full_Name]],tblF42023[FULL_NAME],tblF42023[DIVISION],"",0,1) | AH20: =_xlfn.XLOOKUP(F6Results_2026[[#This Row],[Full_Name]],tblF42023[FULL_NAME],tblF42023[TOTAL A''S],"",0,1) | AK20: SUBJECTS GRADE SUMMARY TABLE
A21: S4459/0637 | B21: 2026 | C21: 20130243190 | D21: ENOCK LEMBRI MEMOY | E21: PCB | F21: Science | G21: M | H21: {=_xlfn.LET( _xlpm.g, F6Results_2026[[#This Row],[Hist]:[Acco]], _xlpm.pts, _xlfn.MAP(_xlpm.g, _xlfn.LAMBDA(_xlpm.x, IFERROR(VLOOKUP(_xlpm.x, AlevelPts, 2, FALSE), ""))), _xlpm.validPts, _xlfn._xlws.FILTER(_xlpm.pts, ISNUMBER(_xlpm.pts)), _xlpm.allBlank, SUM(--(_xlpm.g=""))=COLUMNS(_xlpm.g), IF( _xlpm.allBlank, "ABS", IFERROR(SUM(_xlpm.validPts), "") ) )} -> 13 | I21: =VLOOKUP(H21,$AO$11:$AP$17,2,TRUE) -> III | J21: GVT | K21: E | L21: E | Q21: C | R21: C | S21: F | Z21: {=SUM(IF(K21:Y21="A",1,0), IF(K21:Y21="B",2,0), IF(K21:Y21="C",3,0), IF(K21:Y21="D",4,0), IF(K21:Y21="E",5,0), IF(K21:Y21="S",6,0), IF(K21:Y21="F",7,0))} -> 23 | AA21: =_xlfn.XLOOKUP(F6Results_2026[[#This Row],[Full_Name]],tblF42023[FULL_NAME],tblF42023[POINTS],"",0,1) | AB21: =_xlfn.XLOOKUP(F6Results_2026[[#This Row],[Full_Name]],tblF42023[FULL_NAME],tblF42023[DIVISION],"",0,1) | AC21: =_xlfn.XLOOKUP(F6Results_2026[[#This Row],[Full_Name]],tblF42023[FULL_NAME],tblF42023[POINTS],"",0,1) | AD21: =IFERROR( INDEX(tblF42023[[HKL]:[CBA]], MATCH(F6Results_2026[[#This Row],[Full_Name]], tblF42023[FULL_NAME], 0), MATCH(F6Results_2026[[#This Row],[Comb]], tblF42023[[#Headers],[HKL]:[CBA]], 0) ), "" ) | AE21: =IFERROR( INDEX(tblF42023[], MATCH(F6Results_2026[[#This Row],[Full_Name]], tblF42023[FULL_NAME], 0), MATCH(F6Results_2026[[#This Row],[Comb]] & "_Q", tblF42023[#Headers], 0) ), "" ) | AF21: =_xlfn.XLOOKUP(F6Results_2026[[#This Row],[Full_Name]],tblF22021[FULL_NAME],tblF22021[POINTS],"",0,1) | AG21: =_xlfn.XLOOKUP(F6Results_2026[[#This Row],[Full_Name]],tblF42023[FULL_NAME],tblF42023[DIVISION],"",0,1) | AH21: =_xlfn.XLOOKUP(F6Results_2026[[#This Row],[Full_Name]],tblF42023[FULL_NAME],tblF42023[TOTAL A''S],"",0,1) | AK21: Subject | AL21: A | AM21: B | AN21: C | AO21: D | AP21: E | AQ21: S | AR21: F | AS21: Total Sat | AT21: KPI % | AU21: Below KPI | AV21: Subject GPA | AW21: GPA Grade
A22: S4459/0589 | B22: 2026 | C22: 20130246103 | D22: MARRY JACKSON MWEMA | E22: PCM | F22: Science | G22: F | H22: {=_xlfn.LET( _xlpm.g, F6Results_2026[[#This Row],[Hist]:[Acco]], _xlpm.pts, _xlfn.MAP(_xlpm.g, _xlfn.LAMBDA(_xlpm.x, IFERROR(VLOOKUP(_xlpm.x, AlevelPts, 2, FALSE), ""))), _xlpm.validPts, _xlfn._xlws.FILTER(_xlpm.pts, ISNUMBER(_xlpm.pts)), _xlpm.allBlank, SUM(--(_xlpm.g=""))=COLUMNS(_xlpm.g), IF( _xlpm.allBlank, "ABS", IFERROR(SUM(_xlpm.validPts), "") ) )} -> 11 | I22: =VLOOKUP(H22,$AO$11:$AP$17,2,TRUE) -> II | J22: ST.JUDE | K22: E | Q22: D | R22: C | U22: D | Z22: {=SUM(IF(K22:Y22="A",1,0), IF(K22:Y22="B",2,0), IF(K22:Y22="C",3,0), IF(K22:Y22="D",4,0), IF(K22:Y22="E",5,0), IF(K22:Y22="S",6,0), IF(K22:Y22="F",7,0))} -> 16 | AA22: =_xlfn.XLOOKUP(F6Results_2026[[#This Row],[Full_Name]],tblF42023[FULL_NAME],tblF42023[POINTS],"",0,1) -> 7 | AB22: =_xlfn.XLOOKUP(F6Results_2026[[#This Row],[Full_Name]],tblF42023[FULL_NAME],tblF42023[DIVISION],"",0,1) -> I | AC22: =_xlfn.XLOOKUP(F6Results_2026[[#This Row],[Full_Name]],tblF42023[FULL_NAME],tblF42023[POINTS],"",0,1) -> 7 | AD22: =IFERROR( INDEX(tblF42023[[HKL]:[CBA]], MATCH(F6Results_2026[[#This Row],[Full_Name]], tblF42023[FULL_NAME], 0), MATCH(F6Results_2026[[#This Row],[Comb]], tblF42023[[#Headers],[HKL]:[CBA]], 0) ), "" ) -> 5 | AE22: =IFERROR( INDEX(tblF42023[], MATCH(F6Results_2026[[#This Row],[Full_Name]], tblF42023[FULL_NAME], 0), MATCH(F6Results_2026[[#This Row],[Comb]] & "_Q", tblF42023[#Headers], 0) ), "" ) -> Y | AF22: =_xlfn.XLOOKUP(F6Results_2026[[#This Row],[Full_Name]],tblF22021[FULL_NAME],tblF22021[POINTS],"",0,1) -> 7 | AG22: =_xlfn.XLOOKUP(F6Results_2026[[#This Row],[Full_Name]],tblF42023[FULL_NAME],tblF42023[DIVISION],"",0,1) -> I | AH22: =_xlfn.XLOOKUP(F6Results_2026[[#This Row],[Full_Name]],tblF42023[FULL_NAME],tblF42023[TOTAL A''S],"",0,1) -> 7 | AK22: General Studies | AL22: =COUNTIFS(Fact_Subject_Grade!$G:$G,"Gs",Fact_Subject_Grade!$H:$H,AL$21) -> 1 | AM22: =COUNTIFS(Fact_Subject_Grade!$G:$G,"Gs",Fact_Subject_Grade!$H:$H,AM$21) -> 0 | AN22: =COUNTIFS(Fact_Subject_Grade!$G:$G,"Gs",Fact_Subject_Grade!$H:$H,AN$21) -> 0 | AO22: =COUNTIFS(Fact_Subject_Grade!$G:$G,"Gs",Fact_Subject_Grade!$H:$H,AO$21) -> 38 | AP22: =COUNTIFS(Fact_Subject_Grade!$G:$G,"Gs",Fact_Subject_Grade!$H:$H,AP$21) -> 98 | AQ22: =COUNTIFS(Fact_Subject_Grade!$G:$G,"Gs",Fact_Subject_Grade!$H:$H,AQ$21) -> 25 | AR22: =COUNTIFS(Fact_Subject_Grade!$G:$G,"Gs",Fact_Subject_Grade!$H:$H,AR$21) -> 27 | AS22: =SUM(AL22:AR22) -> 189 | AT22: =IFERROR((SUMPRODUCT(AL22:AR22,{5,4,3,2,1,0.5,0})/(AS22*5))*100,"") -> 20.26455 | AU22: =SUM(AO22:AR22) -> 188 | AV22: =IFERROR(SUMPRODUCT(AL22:AR22,{1,2,3,4,5,6,7})/AS22,"") -> 5.1957672 | AW22: =IF(AV22="","",IF(AV22<=1.4999,"A-EXCELLENT",IF(AV22<=2.4999,"B-VERY GOOD",IF(AV22<=3.4999,"C-GOOD",IF(AV22<=4.4999,"D-AVERAGE",IF(AV22<=5.4999,"E-SATISFACTORY",IF(AV22<=6.4999,"S-SUBSIDIARY",IF(AV22<=7,"F-FAIL","")))))))) -> E-SATISFACTORY
A23: S4459/0658 | B23: 2026 | C23: 20130246226 | D23: HAPPYNESS JACOB LAZARO | E23: ECA | F23: Business | G23: F | H23: {=_xlfn.LET( _xlpm.g, F6Results_2026[[#This Row],[Hist]:[Acco]], _xlpm.pts, _xlfn.MAP(_xlpm.g, _xlfn.LAMBDA(_xlpm.x, IFERROR(VLOOKUP(_xlpm.x, AlevelPts, 2, FALSE), ""))), _xlpm.validPts, _xlfn._xlws.FILTER(_xlpm.pts, ISNUMBER(_xlpm.pts)), _xlpm.allBlank, SUM(--(_xlpm.g=""))=COLUMNS(_xlpm.g), IF( _xlpm.allBlank, "ABS", IFERROR(SUM(_xlpm.validPts), "") ) )} -> 18 | I23: =VLOOKUP(H23,$AO$11:$AP$17,2,TRUE) -> IV | J23: ST.JUDE | K23: E | L23: S | W23: F | X23: F | Y23: D | Z23: {=SUM(IF(K23:Y23="A",1,0), IF(K23:Y23="B",2,0), IF(K23:Y23="C",3,0), IF(K23:Y23="D",4,0), IF(K23:Y23="E",5,0), IF(K23:Y23="S",6,0), IF(K23:Y23="F",7,0))} -> 29 | AA23: =_xlfn.XLOOKUP(F6Results_2026[[#This Row],[Full_Name]],tblF42023[FULL_NAME],tblF42023[POINTS],"",0,1) -> 12 | AB23: =_xlfn.XLOOKUP(F6Results_2026[[#This Row],[Full_Name]],tblF42023[FULL_NAME],tblF42023[DIVISION],"",0,1) -> I | AC23: =_xlfn.XLOOKUP(F6Results_2026[[#This Row],[Full_Name]],tblF42023[FULL_NAME],tblF42023[POINTS],"",0,1) -> 12 | AD23: =IFERROR( INDEX(tblF42023[[HKL]:[CBA]], MATCH(F6Results_2026[[#This Row],[Full_Name]], tblF42023[FULL_NAME], 0), MATCH(F6Results_2026[[#This Row],[Comb]], tblF42023[[#Headers],[HKL]:[CBA]], 0) ), "" ) | AE23: =IFERROR( INDEX(tblF42023[], MATCH(F6Results_2026[[#This Row],[Full_Name]], tblF42023[FULL_NAME], 0), MATCH(F6Results_2026[[#This Row],[Comb]] & "_Q", tblF42023[#Headers], 0) ), "" ) | AF23: =_xlfn.XLOOKUP(F6Results_2026[[#This Row],[Full_Name]],tblF22021[FULL_NAME],tblF22021[POINTS],"",0,1) -> 10 | AG23: =_xlfn.XLOOKUP(F6Results_2026[[#This Row],[Full_Name]],tblF42023[FULL_NAME],tblF42023[DIVISION],"",0,1) -> I | AH23: =_xlfn.XLOOKUP(F6Results_2026[[#This Row],[Full_Name]],tblF42023[FULL_NAME],tblF42023[TOTAL A''S],"",0,1) -> 2 | AK23: Basic Applied Mathematics | AL23: =COUNTIFS(Fact_Subject_Grade!$G:$G,"Bam",Fact_Subject_Grade!$H:$H,AL$21) -> 0 | AM23: =COUNTIFS(Fact_Subject_Grade!$G:$G,"Bam",Fact_Subject_Grade!$H:$H,AM$21) -> 0 | AN23: =COUNTIFS(Fact_Subject_Grade!$G:$G,"Bam",Fact_Subject_Grade!$H:$H,AN$21) -> 0 | AO23: =COUNTIFS(Fact_Subject_Grade!$G:$G,"Bam",Fact_Subject_Grade!$H:$H,AO$21) -> 0 | AP23: =COUNTIFS(Fact_Subject_Grade!$G:$G,"Bam",Fact_Subject_Grade!$H:$H,AP$21) -> 0 | AQ23: =COUNTIFS(Fact_Subject_Grade!$G:$G,"Bam",Fact_Subject_Grade!$H:$H,AQ$21) -> 0 | AR23: =COUNTIFS(Fact_Subject_Grade!$G:$G,"Bam",Fact_Subject_Grade!$H:$H,AR$21) -> 0 | AS23: =SUM(AL23:AR23) -> 0 | AT23: =IFERROR((SUMPRODUCT(AL23:AR23,{5,4,3,2,1,0.5,0})/(AS23*5))*100,"") | AU23: =SUM(AO23:AR23) -> 0 | AV23: =IFERROR(SUMPRODUCT(AL23:AR23,{1,2,3,4,5,6,7})/AS23,"") | AW23: =IF(AV23="","",IF(AV23<=1.4999,"A-EXCELLENT",IF(AV23<=2.4999,"B-VERY GOOD",IF(AV23<=3.4999,"C-GOOD",IF(AV23<=4.4999,"D-AVERAGE",IF(AV23<=5.4999,"E-SATISFACTORY",IF(AV23<=6.4999,"S-SUBSIDIARY",IF(AV23<=7,"F-FAIL",""))))))))
A24: S4459/0538 | B24: 2026 | C24: 20130246235 | D24: LEAH SARUNI LEKEMBA | E24: HGK | F24: Arts | G24: F | H24: {=_xlfn.LET( _xlpm.g, F6Results_2026[[#This Row],[Hist]:[Acco]], _xlpm.pts, _xlfn.MAP(_xlpm.g, _xlfn.LAMBDA(_xlpm.x, IFERROR(VLOOKUP(_xlpm.x, AlevelPts, 2, FALSE), ""))), _xlpm.validPts, _xlfn._xlws.FILTER(_xlpm.pts, ISNUMBER(_xlpm.pts)), _xlpm.allBlank, SUM(--(_xlpm.g=""))=COLUMNS(_xlpm.g), IF( _xlpm.allBlank, "ABS", IFERROR(SUM(_xlpm.validPts), "") ) )} -> 7 | I24: =VLOOKUP(H24,$AO$11:$AP$17,2,TRUE) -> I | J24: GVT | K24: E | M24: D | N24: B | O24: A | Z24: {=SUM(IF(K24:Y24="A",1,0), IF(K24:Y24="B",2,0), IF(K24:Y24="C",3,0), IF(K24:Y24="D",4,0), IF(K24:Y24="E",5,0), IF(K24:Y24="S",6,0), IF(K24:Y24="F",7,0))} -> 12 | AA24: =_xlfn.XLOOKUP(F6Results_2026[[#This Row],[Full_Name]],tblF42023[FULL_NAME],tblF42023[POINTS],"",0,1) | AB24: =_xlfn.XLOOKUP(F6Results_2026[[#This Row],[Full_Name]],tblF42023[FULL_NAME],tblF42023[DIVISION],"",0,1) | AC24: =_xlfn.XLOOKUP(F6Results_2026[[#This Row],[Full_Name]],tblF42023[FULL_NAME],tblF42023[POINTS],"",0,1) | AD24: =IFERROR( INDEX(tblF42023[[HKL]:[CBA]], MATCH(F6Results_2026[[#This Row],[Full_Name]], tblF42023[FULL_NAME], 0), MATCH(F6Results_2026[[#This Row],[Comb]], tblF42023[[#Headers],[HKL]:[CBA]], 0) ), "" ) | AE24: =IFERROR( INDEX(tblF42023[], MATCH(F6Results_2026[[#This Row],[Full_Name]], tblF42023[FULL_NAME], 0), MATCH(F6Results_2026[[#This Row],[Comb]] & "_Q", tblF42023[#Headers], 0) ), "" ) | AF24: =_xlfn.XLOOKUP(F6Results_2026[[#This Row],[Full_Name]],tblF22021[FULL_NAME],tblF22021[POINTS],"",0,1) | AG24: =_xlfn.XLOOKUP(F6Results_2026[[#This Row],[Full_Name]],tblF42023[FULL_NAME],tblF42023[DIVISION],"",0,1) | AH24: =_xlfn.XLOOKUP(F6Results_2026[[#This Row],[Full_Name]],tblF42023[FULL_NAME],tblF42023[TOTAL A''S],"",0,1) | AK24: History | AL24: =COUNTIFS(Fact_Subject_Grade!$G:$G,"Hist",Fact_Subject_Grade!$H:$H,AL$21) -> 1 | AM24: =COUNTIFS(Fact_Subject_Grade!$G:$G,"Hist",Fact_Subject_Grade!$H:$H,AM$21) -> 1 | AN24: =COUNTIFS(Fact_Subject_Grade!$G:$G,"Hist",Fact_Subject_Grade!$H:$H,AN$21) -> 21 | AO24: =COUNTIFS(Fact_Subject_Grade!$G:$G,"Hist",Fact_Subject_Grade!$H:$H,AO$21) -> 27 | AP24: =COUNTIFS(Fact_Subject_Grade!$G:$G,"Hist",Fact_Subject_Grade!$H:$H,AP$21) -> 2 | AQ24: =COUNTIFS(Fact_Subject_Grade!$G:$G,"Hist",Fact_Subject_Grade!$H:$H,AQ$21) -> 0 | AR24: =COUNTIFS(Fact_Subject_Grade!$G:$G,"Hist",Fact_Subject_Grade!$H:$H,AR$21) -> 0 | AS24: =SUM(AL24:AR24) -> 52 | AT24: =IFERROR((SUMPRODUCT(AL24:AR24,{5,4,3,2,1,0.5,0})/(AS24*5))*100,"") -> 49.230769 | AU24: =SUM(AO24:AR24) -> 29 | AV24: =IFERROR(SUMPRODUCT(AL24:AR24,{1,2,3,4,5,6,7})/AS24,"") -> 3.5384615 | AW24: =IF(AV24="","",IF(AV24<=1.4999,"A-EXCELLENT",IF(AV24<=2.4999,"B-VERY GOOD",IF(AV24<=3.4999,"C-GOOD",IF(AV24<=4.4999,"D-AVERAGE",IF(AV24<=5.4999,"E-SATISFACTORY",IF(AV24<=6.4999,"S-SUBSIDIARY",IF(AV24<=7,"F-FAIL","")))))))) -> D-AVERAGE
A25: S4459/0594 | B25: 2026 | C25: 20130253069 | D25: BABAETU LOISHIYE SARUNI | E25: PCM | F25: Science | G25: M | H25: {=_xlfn.LET( _xlpm.g, F6Results_2026[[#This Row],[Hist]:[Acco]], _xlpm.pts, _xlfn.MAP(_xlpm.g, _xlfn.LAMBDA(_xlpm.x, IFERROR(VLOOKUP(_xlpm.x, AlevelPts, 2, FALSE), ""))), _xlpm.validPts, _xlfn._xlws.FILTER(_xlpm.pts, ISNUMBER(_xlpm.pts)), _xlpm.allBlank, SUM(--(_xlpm.g=""))=COLUMNS(_xlpm.g), IF( _xlpm.allBlank, "ABS", IFERROR(SUM(_xlpm.validPts), "") ) )} -> 16 | I25: =VLOOKUP(H25,$AO$11:$AP$17,2,TRUE) -> III | J25: ST.JUDE | K25: E | Q25: E | R25: F | U25: D | Z25: {=SUM(IF(K25:Y25="A",1,0), IF(K25:Y25="B",2,0), IF(K25:Y25="C",3,0), IF(K25:Y25="D",4,0), IF(K25:Y25="E",5,0), IF(K25:Y25="S",6,0), IF(K25:Y25="F",7,0))} -> 21 | AA25: =_xlfn.XLOOKUP(F6Results_2026[[#This Row],[Full_Name]],tblF42023[FULL_NAME],tblF42023[POINTS],"",0,1) -> 7 | AB25: =_xlfn.XLOOKUP(F6Results_2026[[#This Row],[Full_Name]],tblF42023[FULL_NAME],tblF42023[DIVISION],"",0,1) -> I | AC25: =_xlfn.XLOOKUP(F6Results_2026[[#This Row],[Full_Name]],tblF42023[FULL_NAME],tblF42023[POINTS],"",0,1) -> 7 | AD25: =IFERROR( INDEX(tblF42023[[HKL]:[CBA]], MATCH(F6Results_2026[[#This Row],[Full_Name]], tblF42023[FULL_NAME], 0), MATCH(F6Results_2026[[#This Row],[Comb]], tblF42023[[#Headers],[HKL]:[CBA]], 0) ), "" ) -> 5 | AE25: =IFERROR( INDEX(tblF42023[], MATCH(F6Results_2026[[#This Row],[Full_Name]], tblF42023[FULL_NAME], 0), MATCH(F6Results_2026[[#This Row],[Comb]] & "_Q", tblF42023[#Headers], 0) ), "" ) -> Y | AF25: =_xlfn.XLOOKUP(F6Results_2026[[#This Row],[Full_Name]],tblF22021[FULL_NAME],tblF22021[POINTS],"",0,1) -> 7 | AG25: =_xlfn.XLOOKUP(F6Results_2026[[#This Row],[Full_Name]],tblF42023[FULL_NAME],tblF42023[DIVISION],"",0,1) -> I | AH25: =_xlfn.XLOOKUP(F6Results_2026[[#This Row],[Full_Name]],tblF42023[FULL_NAME],tblF42023[TOTAL A''S],"",0,1) -> 7 | AK25: Geography | AL25: =COUNTIFS(Fact_Subject_Grade!$G:$G,"Geo",Fact_Subject_Grade!$H:$H,AL$21) -> 3 | AM25: =COUNTIFS(Fact_Subject_Grade!$G:$G,"Geo",Fact_Subject_Grade!$H:$H,AM$21) -> 18 | AN25: =COUNTIFS(Fact_Subject_Grade!$G:$G,"Geo",Fact_Subject_Grade!$H:$H,AN$21) -> 39 | AO25: =COUNTIFS(Fact_Subject_Grade!$G:$G,"Geo",Fact_Subject_Grade!$H:$H,AO$21) -> 16 | AP25: =COUNTIFS(Fact_Subject_Grade!$G:$G,"Geo",Fact_Subject_Grade!$H:$H,AP$21) -> 3 | AQ25: =COUNTIFS(Fact_Subject_Grade!$G:$G,"Geo",Fact_Subject_Grade!$H:$H,AQ$21) -> 0 | AR25: =COUNTIFS(Fact_Subject_Grade!$G:$G,"Geo",Fact_Subject_Grade!$H:$H,AR$21) -> 0 | AS25: =SUM(AL25:AR25) -> 79 | AT25: =IFERROR((SUMPRODUCT(AL25:AR25,{5,4,3,2,1,0.5,0})/(AS25*5))*100,"") -> 60.506329 | AU25: =SUM(AO25:AR25) -> 19 | AV25: =IFERROR(SUMPRODUCT(AL25:AR25,{1,2,3,4,5,6,7})/AS25,"") -> 2.9746835 | AW25: =IF(AV25="","",IF(AV25<=1.4999,"A-EXCELLENT",IF(AV25<=2.4999,"B-VERY GOOD",IF(AV25<=3.4999,"C-GOOD",IF(AV25<=4.4999,"D-AVERAGE",IF(AV25<=5.4999,"E-SATISFACTORY",IF(AV25<=6.4999,"S-SUBSIDIARY",IF(AV25<=7,"F-FAIL","")))))))) -> C-GOOD
A26: S4459/0593 | B26: 2026 | C26: 20130267516 | D26: ALEKIUS SLIVERY KAZOBA | E26: PCM | F26: Science | G26: M | H26: {=_xlfn.LET( _xlpm.g, F6Results_2026[[#This Row],[Hist]:[Acco]], _xlpm.pts, _xlfn.MAP(_xlpm.g, _xlfn.LAMBDA(_xlpm.x, IFERROR(VLOOKUP(_xlpm.x, AlevelPts, 2, FALSE), ""))), _xlpm.validPts, _xlfn._xlws.FILTER(_xlpm.pts, ISNUMBER(_xlpm.pts)), _xlpm.allBlank, SUM(--(_xlpm.g=""))=COLUMNS(_xlpm.g), IF( _xlpm.allBlank, "ABS", IFERROR(SUM(_xlpm.validPts), "") ) )} -> 11 | I26: =VLOOKUP(H26,$AO$11:$AP$17,2,TRUE) -> II | J26: ST.JUDE | K26: S | Q26: E | R26: C | U26: C | Z26: {=SUM(IF(K26:Y26="A",1,0), IF(K26:Y26="B",2,0), IF(K26:Y26="C",3,0), IF(K26:Y26="D",4,0), IF(K26:Y26="E",5,0), IF(K26:Y26="S",6,0), IF(K26:Y26="F",7,0))} -> 17 | AA26: =_xlfn.XLOOKUP(F6Results_2026[[#This Row],[Full_Name]],tblF42023[FULL_NAME],tblF42023[POINTS],"",0,1) -> 8 | AB26: =_xlfn.XLOOKUP(F6Results_2026[[#This Row],[Full_Name]],tblF42023[FULL_NAME],tblF42023[DIVISION],"",0,1) -> I | AC26: =_xlfn.XLOOKUP(F6Results_2026[[#This Row],[Full_Name]],tblF42023[FULL_NAME],tblF42023[POINTS],"",0,1) -> 8 | AD26: =IFERROR( INDEX(tblF42023[[HKL]:[CBA]], MATCH(F6Results_2026[[#This Row],[Full_Name]], tblF42023[FULL_NAME], 0), MATCH(F6Results_2026[[#This Row],[Comb]], tblF42023[[#Headers],[HKL]:[CBA]], 0) ), "" ) -> 4 | AE26: =IFERROR( INDEX(tblF42023[], MATCH(F6Results_2026[[#This Row],[Full_Name]], tblF42023[FULL_NAME], 0), MATCH(F6Results_2026[[#This Row],[Comb]] & "_Q", tblF42023[#Headers], 0) ), "" ) -> Y | AF26: =_xlfn.XLOOKUP(F6Results_2026[[#This Row],[Full_Name]],tblF22021[FULL_NAME],tblF22021[POINTS],"",0,1) -> 7 | AG26: =_xlfn.XLOOKUP(F6Results_2026[[#This Row],[Full_Name]],tblF42023[FULL_NAME],tblF42023[DIVISION],"",0,1) -> I | AH26: =_xlfn.XLOOKUP(F6Results_2026[[#This Row],[Full_Name]],tblF42023[FULL_NAME],tblF42023[TOTAL A''S],"",0,1) -> 6 | AK26: Kiswahili | AL26: =COUNTIFS(Fact_Subject_Grade!$G:$G,"Kisw",Fact_Subject_Grade!$H:$H,AL$21) -> 28 | AM26: =COUNTIFS(Fact_Subject_Grade!$G:$G,"Kisw",Fact_Subject_Grade!$H:$H,AM$21) -> 0 | AN26: =COUNTIFS(Fact_Subject_Grade!$G:$G,"Kisw",Fact_Subject_Grade!$H:$H,AN$21) -> 0 | AO26: =COUNTIFS(Fact_Subject_Grade!$G:$G,"Kisw",Fact_Subject_Grade!$H:$H,AO$21) -> 0 | AP26: =COUNTIFS(Fact_Subject_Grade!$G:$G,"Kisw",Fact_Subject_Grade!$H:$H,AP$21) -> 0 | AQ26: =COUNTIFS(Fact_Subject_Grade!$G:$G,"Kisw",Fact_Subject_Grade!$H:$H,AQ$21) -> 0 | AR26: =COUNTIFS(Fact_Subject_Grade!$G:$G,"Kisw",Fact_Subject_Grade!$H:$H,AR$21) -> 0 | AS26: =SUM(AL26:AR26) -> 28 | AT26: =IFERROR((SUMPRODUCT(AL26:AR26,{5,4,3,2,1,0.5,0})/(AS26*5))*100,"") -> 100 | AU26: =SUM(AO26:AR26) -> 0 | AV26: =IFERROR(SUMPRODUCT(AL26:AR26,{1,2,3,4,5,6,7})/AS26,"") -> 1 | AW26: =IF(AV26="","",IF(AV26<=1.4999,"A-EXCELLENT",IF(AV26<=2.4999,"B-VERY GOOD",IF(AV26<=3.4999,"C-GOOD",IF(AV26<=4.4999,"D-AVERAGE",IF(AV26<=5.4999,"E-SATISFACTORY",IF(AV26<=6.4999,"S-SUBSIDIARY",IF(AV26<=7,"F-FAIL","")))))))) -> A-EXCELLENT
A27: S4459/0571 | B27: 2026 | C27: 20130269960 | D27: ERICK DAUDI OLODI | E27: EGM | F27: Business | G27: M | H27: {=_xlfn.LET( _xlpm.g, F6Results_2026[[#This Row],[Hist]:[Acco]], _xlpm.pts, _xlfn.MAP(_xlpm.g, _xlfn.LAMBDA(_xlpm.x, IFERROR(VLOOKUP(_xlpm.x, AlevelPts, 2, FALSE), ""))), _xlpm.validPts, _xlfn._xlws.FILTER(_xlpm.pts, ISNUMBER(_xlpm.pts)), _xlpm.allBlank, SUM(--(_xlpm.g=""))=COLUMNS(_xlpm.g), IF( _xlpm.allBlank, "ABS", IFERROR(SUM(_xlpm.validPts), "") ) )} -> 10 | I27: =VLOOKUP(H27,$AO$11:$AP$17,2,TRUE) -> II | J27: ST.JUDE | K27: E | N27: B | U27: E | W27: C | Z27: {=SUM(IF(K27:Y27="A",1,0), IF(K27:Y27="B",2,0), IF(K27:Y27="C",3,0), IF(K27:Y27="D",4,0), IF(K27:Y27="E",5,0), IF(K27:Y27="S",6,0), IF(K27:Y27="F",7,0))} -> 15 | AA27: =_xlfn.XLOOKUP(F6Results_2026[[#This Row],[Full_Name]],tblF42023[FULL_NAME],tblF42023[POINTS],"",0,1) -> 11 | AB27: =_xlfn.XLOOKUP(F6Results_2026[[#This Row],[Full_Name]],tblF42023[FULL_NAME],tblF42023[DIVISION],"",0,1) -> I | AC27: =_xlfn.XLOOKUP(F6Results_2026[[#This Row],[Full_Name]],tblF42023[FULL_NAME],tblF42023[POINTS],"",0,1) -> 11 | AD27: =IFERROR( INDEX(tblF42023[[HKL]:[CBA]], MATCH(F6Results_2026[[#This Row],[Full_Name]], tblF42023[FULL_NAME], 0), MATCH(F6Results_2026[[#This Row],[Comb]], tblF42023[[#Headers],[HKL]:[CBA]], 0) ), "" ) -> 6 | AE27: =IFERROR( INDEX(tblF42023[], MATCH(F6Results_2026[[#This Row],[Full_Name]], tblF42023[FULL_NAME], 0), MATCH(F6Results_2026[[#This Row],[Comb]] & "_Q", tblF42023[#Headers], 0) ), "" ) -> Y | AF27: =_xlfn.XLOOKUP(F6Results_2026[[#This Row],[Full_Name]],tblF22021[FULL_NAME],tblF22021[POINTS],"",0,1) -> 7 | AG27: =_xlfn.XLOOKUP(F6Results_2026[[#This Row],[Full_Name]],tblF42023[FULL_NAME],tblF42023[DIVISION],"",0,1) -> I | AH27: =_xlfn.XLOOKUP(F6Results_2026[[#This Row],[Full_Name]],tblF42023[FULL_NAME],tblF42023[TOTAL A''S],"",0,1) -> 3 | AK27: English | AL27: =COUNTIFS(Fact_Subject_Grade!$G:$G,"Engl",Fact_Subject_Grade!$H:$H,AL$21) -> 0 | AM27: =COUNTIFS(Fact_Subject_Grade!$G:$G,"Engl",Fact_Subject_Grade!$H:$H,AM$21) -> 4 | AN27: =COUNTIFS(Fact_Subject_Grade!$G:$G,"Engl",Fact_Subject_Grade!$H:$H,AN$21) -> 7 | AO27: =COUNTIFS(Fact_Subject_Grade!$G:$G,"Engl",Fact_Subject_Grade!$H:$H,AO$21) -> 12 | AP27: =COUNTIFS(Fact_Subject_Grade!$G:$G,"Engl",Fact_Subject_Grade!$H:$H,AP$21) -> 1 | AQ27: =COUNTIFS(Fact_Subject_Grade!$G:$G,"Engl",Fact_Subject_Grade!$H:$H,AQ$21) -> 0 | AR27: =COUNTIFS(Fact_Subject_Grade!$G:$G,"Engl",Fact_Subject_Grade!$H:$H,AR$21) -> 0 | AS27: =SUM(AL27:AR27) -> 24 | AT27: =IFERROR((SUMPRODUCT(AL27:AR27,{5,4,3,2,1,0.5,0})/(AS27*5))*100,"") -> 51.666667 | AU27: =SUM(AO27:AR27) -> 13 | AV27: =IFERROR(SUMPRODUCT(AL27:AR27,{1,2,3,4,5,6,7})/AS27,"") -> 3.4166667 | AW27: =IF(AV27="","",IF(AV27<=1.4999,"A-EXCELLENT",IF(AV27<=2.4999,"B-VERY GOOD",IF(AV27<=3.4999,"C-GOOD",IF(AV27<=4.4999,"D-AVERAGE",IF(AV27<=5.4999,"E-SATISFACTORY",IF(AV27<=6.4999,"S-SUBSIDIARY",IF(AV27<=7,"F-FAIL","")))))))) -> C-GOOD
A28: S4459/0603 | B28: 2026 | C28: 20130282968 | D28: JOSEPH DIDAS SWAY | E28: PCM | F28: Science | G28: M | H28: {=_xlfn.LET( _xlpm.g, F6Results_2026[[#This Row],[Hist]:[Acco]], _xlpm.pts, _xlfn.MAP(_xlpm.g, _xlfn.LAMBDA(_xlpm.x, IFERROR(VLOOKUP(_xlpm.x, AlevelPts, 2, FALSE), ""))), _xlpm.validPts, _xlfn._xlws.FILTER(_xlpm.pts, ISNUMBER(_xlpm.pts)), _xlpm.allBlank, SUM(--(_xlpm.g=""))=COLUMNS(_xlpm.g), IF( _xlpm.allBlank, "ABS", IFERROR(SUM(_xlpm.validPts), "") ) )} -> 10 | I28: =VLOOKUP(H28,$AO$11:$AP$17,2,TRUE) -> II | J28: GVT | K28: F | Q28: C | R28: D | U28: C | Z28: {=SUM(IF(K28:Y28="A",1,0), IF(K28:Y28="B",2,0), IF(K28:Y28="C",3,0), IF(K28:Y28="D",4,0), IF(K28:Y28="E",5,0), IF(K28:Y28="S",6,0), IF(K28:Y28="F",7,0))} -> 17 | AA28: =_xlfn.XLOOKUP(F6Results_2026[[#This Row],[Full_Name]],tblF42023[FULL_NAME],tblF42023[POINTS],"",0,1) | AB28: =_xlfn.XLOOKUP(F6Results_2026[[#This Row],[Full_Name]],tblF42023[FULL_NAME],tblF42023[DIVISION],"",0,1) | AC28: =_xlfn.XLOOKUP(F6Results_2026[[#This Row],[Full_Name]],tblF42023[FULL_NAME],tblF42023[POINTS],"",0,1) | AD28: =IFERROR( INDEX(tblF42023[[HKL]:[CBA]], MATCH(F6Results_2026[[#This Row],[Full_Name]], tblF42023[FULL_NAME], 0), MATCH(F6Results_2026[[#This Row],[Comb]], tblF42023[[#Headers],[HKL]:[CBA]], 0) ), "" ) | AE28: =IFERROR( INDEX(tblF42023[], MATCH(F6Results_2026[[#This Row],[Full_Name]], tblF42023[FULL_NAME], 0), MATCH(F6Results_2026[[#This Row],[Comb]] & "_Q", tblF42023[#Headers], 0) ), "" ) | AF28: =_xlfn.XLOOKUP(F6Results_2026[[#This Row],[Full_Name]],tblF22021[FULL_NAME],tblF22021[POINTS],"",0,1) | AG28: =_xlfn.XLOOKUP(F6Results_2026[[#This Row],[Full_Name]],tblF42023[FULL_NAME],tblF42023[DIVISION],"",0,1) | AH28: =_xlfn.XLOOKUP(F6Results_2026[[#This Row],[Full_Name]],tblF42023[FULL_NAME],tblF42023[TOTAL A''S],"",0,1) | AK28: Physics | AL28: =COUNTIFS(Fact_Subject_Grade!$G:$G,"Phy",Fact_Subject_Grade!$H:$H,AL$21) -> 0 | AM28: =COUNTIFS(Fact_Subject_Grade!$G:$G,"Phy",Fact_Subject_Grade!$H:$H,AM$21) -> 0 | AN28: =COUNTIFS(Fact_Subject_Grade!$G:$G,"Phy",Fact_Subject_Grade!$H:$H,AN$21) -> 15 | AO28: =COUNTIFS(Fact_Subject_Grade!$G:$G,"Phy",Fact_Subject_Grade!$H:$H,AO$21) -> 22 | AP28: =COUNTIFS(Fact_Subject_Grade!$G:$G,"Phy",Fact_Subject_Grade!$H:$H,AP$21) -> 22 | AQ28: =COUNTIFS(Fact_Subject_Grade!$G:$G,"Phy",Fact_Subject_Grade!$H:$H,AQ$21) -> 6 | AR28: =COUNTIFS(Fact_Subject_Grade!$G:$G,"Phy",Fact_Subject_Grade!$H:$H,AR$21) -> 16 | AS28: =SUM(AL28:AR28) -> 81 | AT28: =IFERROR((SUMPRODUCT(AL28:AR28,{5,4,3,2,1,0.5,0})/(AS28*5))*100,"") -> 28.148148 | AU28: =SUM(AO28:AR28) -> 66 | AV28: =IFERROR(SUMPRODUCT(AL28:AR28,{1,2,3,4,5,6,7})/AS28,"") -> 4.8271605 | AW28: =IF(AV28="","",IF(AV28<=1.4999,"A-EXCELLENT",IF(AV28<=2.4999,"B-VERY GOOD",IF(AV28<=3.4999,"C-GOOD",IF(AV28<=4.4999,"D-AVERAGE",IF(AV28<=5.4999,"E-SATISFACTORY",IF(AV28<=6.4999,"S-SUBSIDIARY",IF(AV28<=7,"F-FAIL","")))))))) -> E-SATISFACTORY
A29: S4459/0662 | B29: 2026 | C29: 20130285592 | D29: ALLEN HUSSEIN IDDI | E29: ECA | F29: Business | G29: M | H29: {=_xlfn.LET( _xlpm.g, F6Results_2026[[#This Row],[Hist]:[Acco]], _xlpm.pts, _xlfn.MAP(_xlpm.g, _xlfn.LAMBDA(_xlpm.x, IFERROR(VLOOKUP(_xlpm.x, AlevelPts, 2, FALSE), ""))), _xlpm.validPts, _xlfn._xlws.FILTER(_xlpm.pts, ISNUMBER(_xlpm.pts)), _xlpm.allBlank, SUM(--(_xlpm.g=""))=COLUMNS(_xlpm.g), IF( _xlpm.allBlank, "ABS", IFERROR(SUM(_xlpm.validPts), "") ) )} -> 18 | I29: =VLOOKUP(H29,$AO$11:$AP$17,2,TRUE) -> IV | J29: ST.JUDE | K29: E | L29: F | W29: F | X29: F | Y29: D | Z29: {=SUM(IF(K29:Y29="A",1,0), IF(K29:Y29="B",2,0), IF(K29:Y29="C",3,0), IF(K29:Y29="D",4,0), IF(K29:Y29="E",5,0), IF(K29:Y29="S",6,0), IF(K29:Y29="F",7,0))} -> 30 | AA29: =_xlfn.XLOOKUP(F6Results_2026[[#This Row],[Full_Name]],tblF42023[FULL_NAME],tblF42023[POINTS],"",0,1) -> 10 | AB29: =_xlfn.XLOOKUP(F6Results_2026[[#This Row],[Full_Name]],tblF42023[FULL_NAME],tblF42023[DIVISION],"",0,1) -> I | AC29: =_xlfn.XLOOKUP(F6Results_2026[[#This Row],[Full_Name]],tblF42023[FULL_NAME],tblF42023[POINTS],"",0,1) -> 10 | AD29: =IFERROR( INDEX(tblF42023[[HKL]:[CBA]], MATCH(F6Results_2026[[#This Row],[Full_Name]], tblF42023[FULL_NAME], 0), MATCH(F6Results_2026[[#This Row],[Comb]], tblF42023[[#Headers],[HKL]:[CBA]], 0) ), "" ) | AE29: =IFERROR( INDEX(tblF42023[], MATCH(F6Results_2026[[#This Row],[Full_Name]], tblF42023[FULL_NAME], 0), MATCH(F6Results_2026[[#This Row],[Comb]] & "_Q", tblF42023[#Headers], 0) ), "" ) | AF29: =_xlfn.XLOOKUP(F6Results_2026[[#This Row],[Full_Name]],tblF22021[FULL_NAME],tblF22021[POINTS],"",0,1) -> 8 | AG29: =_xlfn.XLOOKUP(F6Results_2026[[#This Row],[Full_Name]],tblF42023[FULL_NAME],tblF42023[DIVISION],"",0,1) -> I | AH29: =_xlfn.XLOOKUP(F6Results_2026[[#This Row],[Full_Name]],tblF42023[FULL_NAME],tblF42023[TOTAL A''S],"",0,1) -> 4 | AK29: Chemistry | AL29: =COUNTIFS(Fact_Subject_Grade!$G:$G,"Chem",Fact_Subject_Grade!$H:$H,AL$21) -> 0 | AM29: =COUNTIFS(Fact_Subject_Grade!$G:$G,"Chem",Fact_Subject_Grade!$H:$H,AM$21) -> 0 | AN29: =COUNTIFS(Fact_Subject_Grade!$G:$G,"Chem",Fact_Subject_Grade!$H:$H,AN$21) -> 42 | AO29: =COUNTIFS(Fact_Subject_Grade!$G:$G,"Chem",Fact_Subject_Grade!$H:$H,AO$21) -> 28 | AP29: =COUNTIFS(Fact_Subject_Grade!$G:$G,"Chem",Fact_Subject_Grade!$H:$H,AP$21) -> 8 | AQ29: =COUNTIFS(Fact_Subject_Grade!$G:$G,"Chem",Fact_Subject_Grade!$H:$H,AQ$21) -> 0 | AR29: =COUNTIFS(Fact_Subject_Grade!$G:$G,"Chem",Fact_Subject_Grade!$H:$H,AR$21) -> 12 | AS29: =SUM(AL29:AR29) -> 90 | AT29: =IFERROR((SUMPRODUCT(AL29:AR29,{5,4,3,2,1,0.5,0})/(AS29*5))*100,"") -> 42.222222 | AU29: =SUM(AO29:AR29) -> 48 | AV29: =IFERROR(SUMPRODUCT(AL29:AR29,{1,2,3,4,5,6,7})/AS29,"") -> 4.0222222 | AW29: =IF(AV29="","",IF(AV29<=1.4999,"A-EXCELLENT",IF(AV29<=2.4999,"B-VERY GOOD",IF(AV29<=3.4999,"C-GOOD",IF(AV29<=4.4999,"D-AVERAGE",IF(AV29<=5.4999,"E-SATISFACTORY",IF(AV29<=6.4999,"S-SUBSIDIARY",IF(AV29<=7,"F-FAIL","")))))))) -> D-AVERAGE
A30: S4459/0568 | B30: 2026 | C30: 20130285593 | D30: ALLY YUSUPH MSANGI | E30: EGM | F30: Business | G30: M | H30: {=_xlfn.LET( _xlpm.g, F6Results_2026[[#This Row],[Hist]:[Acco]], _xlpm.pts, _xlfn.MAP(_xlpm.g, _xlfn.LAMBDA(_xlpm.x, IFERROR(VLOOKUP(_xlpm.x, AlevelPts, 2, FALSE), ""))), _xlpm.validPts, _xlfn._xlws.FILTER(_xlpm.pts, ISNUMBER(_xlpm.pts)), _xlpm.allBlank, SUM(--(_xlpm.g=""))=COLUMNS(_xlpm.g), IF( _xlpm.allBlank, "ABS", IFERROR(SUM(_xlpm.validPts), "") ) )} -> 11 | I30: =VLOOKUP(H30,$AO$11:$AP$17,2,TRUE) -> II | J30: ST.JUDE | K30: F | N30: B | U30: E | W30: D | Z30: {=SUM(IF(K30:Y30="A",1,0), IF(K30:Y30="B",2,0), IF(K30:Y30="C",3,0), IF(K30:Y30="D",4,0), IF(K30:Y30="E",5,0), IF(K30:Y30="S",6,0), IF(K30:Y30="F",7,0))} -> 18 | AA30: =_xlfn.XLOOKUP(F6Results_2026[[#This Row],[Full_Name]],tblF42023[FULL_NAME],tblF42023[POINTS],"",0,1) -> 12 | AB30: =_xlfn.XLOOKUP(F6Results_2026[[#This Row],[Full_Name]],tblF42023[FULL_NAME],tblF42023[DIVISION],"",0,1) -> I | AC30: =_xlfn.XLOOKUP(F6Results_2026[[#This Row],[Full_Name]],tblF42023[FULL_NAME],tblF42023[POINTS],"",0,1) -> 12 | AD30: =IFERROR( INDEX(tblF42023[[HKL]:[CBA]], MATCH(F6Results_2026[[#This Row],[Full_Name]], tblF42023[FULL_NAME], 0), MATCH(F6Results_2026[[#This Row],[Comb]], tblF42023[[#Headers],[HKL]:[CBA]], 0) ), "" ) -> 6 | AE30: =IFERROR( INDEX(tblF42023[], MATCH(F6Results_2026[[#This Row],[Full_Name]], tblF42023[FULL_NAME], 0), MATCH(F6Results_2026[[#This Row],[Comb]] & "_Q", tblF42023[#Headers], 0) ), "" ) -> Y | AF30: =_xlfn.XLOOKUP(F6Results_2026[[#This Row],[Full_Name]],tblF22021[FULL_NAME],tblF22021[POINTS],"",0,1) -> 9 | AG30: =_xlfn.XLOOKUP(F6Results_2026[[#This Row],[Full_Name]],tblF42023[FULL_NAME],tblF42023[DIVISION],"",0,1) -> I | AH30: =_xlfn.XLOOKUP(F6Results_2026[[#This Row],[Full_Name]],tblF42023[FULL_NAME],tblF42023[TOTAL A''S],"",0,1) -> 3 | AK30: Biology | AL30: =COUNTIFS(Fact_Subject_Grade!$G:$G,"Biol",Fact_Subject_Grade!$H:$H,AL$21) -> 0 | AM30: =COUNTIFS(Fact_Subject_Grade!$G:$G,"Biol",Fact_Subject_Grade!$H:$H,AM$21) -> 0 | AN30: =COUNTIFS(Fact_Subject_Grade!$G:$G,"Biol",Fact_Subject_Grade!$H:$H,AN$21) -> 25 | AO30: =COUNTIFS(Fact_Subject_Grade!$G:$G,"Biol",Fact_Subject_Grade!$H:$H,AO$21) -> 7 | AP30: =COUNTIFS(Fact_Subject_Grade!$G:$G,"Biol",Fact_Subject_Grade!$H:$H,AP$21) -> 0 | AQ30: =COUNTIFS(Fact_Subject_Grade!$G:$G,"Biol",Fact_Subject_Grade!$H:$H,AQ$21) -> 0 | AR30: =COUNTIFS(Fact_Subject_Grade!$G:$G,"Biol",Fact_Subject_Grade!$H:$H,AR$21) -> 30 | AS30: =SUM(AL30:AR30) -> 62 | AT30: =IFERROR((SUMPRODUCT(AL30:AR30,{5,4,3,2,1,0.5,0})/(AS30*5))*100,"") -> 28.709677 | AU30: =SUM(AO30:AR30) -> 37 | AV30: =IFERROR(SUMPRODUCT(AL30:AR30,{1,2,3,4,5,6,7})/AS30,"") -> 5.0483871 | AW30: =IF(AV30="","",IF(AV30<=1.4999,"A-EXCELLENT",IF(AV30<=2.4999,"B-VERY GOOD",IF(AV30<=3.4999,"C-GOOD",IF(AV30<=4.4999,"D-AVERAGE",IF(AV30<=5.4999,"E-SATISFACTORY",IF(AV30<=6.4999,"S-SUBSIDIARY",IF(AV30<=7,"F-FAIL","")))))))) -> E-SATISFACTORY
A31: S4459/0569 | B31: 2026 | C31: 20130285595 | D31: ARNOLD ERNEST TSAKARA | E31: EGM | F31: Business | G31: M | H31: {=_xlfn.LET( _xlpm.g, F6Results_2026[[#This Row],[Hist]:[Acco]], _xlpm.pts, _xlfn.MAP(_xlpm.g, _xlfn.LAMBDA(_xlpm.x, IFERROR(VLOOKUP(_xlpm.x, AlevelPts, 2, FALSE), ""))), _xlpm.validPts, _xlfn._xlws.FILTER(_xlpm.pts, ISNUMBER(_xlpm.pts)), _xlpm.allBlank, SUM(--(_xlpm.g=""))=COLUMNS(_xlpm.g), IF( _xlpm.allBlank, "ABS", IFERROR(SUM(_xlpm.validPts), "") ) )} -> 11 | I31: =VLOOKUP(H31,$AO$11:$AP$17,2,TRUE) -> II | J31: ST.JUDE | K31: E | N31: C | U31: E | W31: C | Z31: {=SUM(IF(K31:Y31="A",1,0), IF(K31:Y31="B",2,0), IF(K31:Y31="C",3,0), IF(K31:Y31="D",4,0), IF(K31:Y31="E",5,0), IF(K31:Y31="S",6,0), IF(K31:Y31="F",7,0))} -> 16 | AA31: =_xlfn.XLOOKUP(F6Results_2026[[#This Row],[Full_Name]],tblF42023[FULL_NAME],tblF42023[POINTS],"",0,1) -> 11 | AB31: =_xlfn.XLOOKUP(F6Results_2026[[#This Row],[Full_Name]],tblF42023[FULL_NAME],tblF42023[DIVISION],"",0,1) -> I | AC31: =_xlfn.XLOOKUP(F6Results_2026[[#This Row],[Full_Name]],tblF42023[FULL_NAME],tblF42023[POINTS],"",0,1) -> 11 | AD31: =IFERROR( INDEX(tblF42023[[HKL]:[CBA]], MATCH(F6Results_2026[[#This Row],[Full_Name]], tblF42023[FULL_NAME], 0), MATCH(F6Results_2026[[#This Row],[Comb]], tblF42023[[#Headers],[HKL]:[CBA]], 0) ), "" ) -> 5 | AE31: =IFERROR( INDEX(tblF42023[], MATCH(F6Results_2026[[#This Row],[Full_Name]], tblF42023[FULL_NAME], 0), MATCH(F6Results_2026[[#This Row],[Comb]] & "_Q", tblF42023[#Headers], 0) ), "" ) -> Y | AF31: =_xlfn.XLOOKUP(F6Results_2026[[#This Row],[Full_Name]],tblF22021[FULL_NAME],tblF22021[POINTS],"",0,1) -> 7 | AG31: =_xlfn.XLOOKUP(F6Results_2026[[#This Row],[Full_Name]],tblF42023[FULL_NAME],tblF42023[DIVISION],"",0,1) -> I | AH31: =_xlfn.XLOOKUP(F6Results_2026[[#This Row],[Full_Name]],tblF42023[FULL_NAME],tblF42023[TOTAL A''S],"",0,1) -> 3 | AK31: Agriculture | AL31: =COUNTIFS(Fact_Subject_Grade!$G:$G,"Agr",Fact_Subject_Grade!$H:$H,AL$21) -> 0 | AM31: =COUNTIFS(Fact_Subject_Grade!$G:$G,"Agr",Fact_Subject_Grade!$H:$H,AM$21) -> 0 | AN31: =COUNTIFS(Fact_Subject_Grade!$G:$G,"Agr",Fact_Subject_Grade!$H:$H,AN$21) -> 10 | AO31: =COUNTIFS(Fact_Subject_Grade!$G:$G,"Agr",Fact_Subject_Grade!$H:$H,AO$21) -> 4 | AP31: =COUNTIFS(Fact_Subject_Grade!$G:$G,"Agr",Fact_Subject_Grade!$H:$H,AP$21) -> 0 | AQ31: =COUNTIFS(Fact_Subject_Grade!$G:$G,"Agr",Fact_Subject_Grade!$H:$H,AQ$21) -> 0 | AR31: =COUNTIFS(Fact_Subject_Grade!$G:$G,"Agr",Fact_Subject_Grade!$H:$H,AR$21) -> 2 | AS31: =SUM(AL31:AR31) -> 16 | AT31: =IFERROR((SUMPRODUCT(AL31:AR31,{5,4,3,2,1,0.5,0})/(AS31*5))*100,"") -> 47.5 | AU31: =SUM(AO31:AR31) -> 6 | AV31: =IFERROR(SUMPRODUCT(AL31:AR31,{1,2,3,4,5,6,7})/AS31,"") -> 3.75 | AW31: =IF(AV31="","",IF(AV31<=1.4999,"A-EXCELLENT",IF(AV31<=2.4999,"B-VERY GOOD",IF(AV31<=3.4999,"C-GOOD",IF(AV31<=4.4999,"D-AVERAGE",IF(AV31<=5.4999,"E-SATISFACTORY",IF(AV31<=6.4999,"S-SUBSIDIARY",IF(AV31<=7,"F-FAIL","")))))))) -> D-AVERAGE
A32: S4459/0570 | B32: 2026 | C32: 20130285602 | D32: DAMAS JOSEPH KIDAYA | E32: EGM | F32: Business | G32: M | H32: {=_xlfn.LET( _xlpm.g, F6Results_2026[[#This Row],[Hist]:[Acco]], _xlpm.pts, _xlfn.MAP(_xlpm.g, _xlfn.LAMBDA(_xlpm.x, IFERROR(VLOOKUP(_xlpm.x, AlevelPts, 2, FALSE), ""))), _xlpm.validPts, _xlfn._xlws.FILTER(_xlpm.pts, ISNUMBER(_xlpm.pts)), _xlpm.allBlank, SUM(--(_xlpm.g=""))=COLUMNS(_xlpm.g), IF( _xlpm.allBlank, "ABS", IFERROR(SUM(_xlpm.validPts), "") ) )} -> 12 | I32: =VLOOKUP(H32,$AO$11:$AP$17,2,TRUE) -> II | J32: ST.JUDE | K32: E | N32: C | U32: E | W32: D | Z32: {=SUM(IF(K32:Y32="A",1,0), IF(K32:Y32="B",2,0), IF(K32:Y32="C",3,0), IF(K32:Y32="D",4,0), IF(K32:Y32="E",5,0), IF(K32:Y32="S",6,0), IF(K32:Y32="F",7,0))} -> 17 | AA32: =_xlfn.XLOOKUP(F6Results_2026[[#This Row],[Full_Name]],tblF42023[FULL_NAME],tblF42023[POINTS],"",0,1) -> 9 | AB32: =_xlfn.XLOOKUP(F6Results_2026[[#This Row],[Full_Name]],tblF42023[FULL_NAME],tblF42023[DIVISION],"",0,1) -> I | AC32: =_xlfn.XLOOKUP(F6Results_2026[[#This Row],[Full_Name]],tblF42023[FULL_NAME],tblF42023[POINTS],"",0,1) -> 9 | AD32: =IFERROR( INDEX(tblF42023[[HKL]:[CBA]], MATCH(F6Results_2026[[#This Row],[Full_Name]], tblF42023[FULL_NAME], 0), MATCH(F6Results_2026[[#This Row],[Comb]], tblF42023[[#Headers],[HKL]:[CBA]], 0) ), "" ) -> 3 | AE32: =IFERROR( INDEX(tblF42023[], MATCH(F6Results_2026[[#This Row],[Full_Name]], tblF42023[FULL_NAME], 0), MATCH(F6Results_2026[[#This Row],[Comb]] & "_Q", tblF42023[#Headers], 0) ), "" ) -> Y | AF32: =_xlfn.XLOOKUP(F6Results_2026[[#This Row],[Full_Name]],tblF22021[FULL_NAME],tblF22021[POINTS],"",0,1) -> 7 | AG32: =_xlfn.XLOOKUP(F6Results_2026[[#This Row],[Full_Name]],tblF42023[FULL_NAME],tblF42023[DIVISION],"",0,1) -> I | AH32: =_xlfn.XLOOKUP(F6Results_2026[[#This Row],[Full_Name]],tblF42023[FULL_NAME],tblF42023[TOTAL A''S],"",0,1) -> 5 | AK32: Advanced Mathematics | AL32: =COUNTIFS(Fact_Subject_Grade!$G:$G,"Adv_Math",Fact_Subject_Grade!$H:$H,AL$21) -> 0 | AM32: =COUNTIFS(Fact_Subject_Grade!$G:$G,"Adv_Math",Fact_Subject_Grade!$H:$H,AM$21) -> 0 | AN32: =COUNTIFS(Fact_Subject_Grade!$G:$G,"Adv_Math",Fact_Subject_Grade!$H:$H,AN$21) -> 10 | AO32: =COUNTIFS(Fact_Subject_Grade!$G:$G,"Adv_Math",Fact_Subject_Grade!$H:$H,AO$21) -> 16 | AP32: =COUNTIFS(Fact_Subject_Grade!$G:$G,"Adv_Math",Fact_Subject_Grade!$H:$H,AP$21) -> 20 | AQ32: =COUNTIFS(Fact_Subject_Grade!$G:$G,"Adv_Math",Fact_Subject_Grade!$H:$H,AQ$21) -> 7 | AR32: =COUNTIFS(Fact_Subject_Grade!$G:$G,"Adv_Math",Fact_Subject_Grade!$H:$H,AR$21) -> 9 | AS32: =SUM(AL32:AR32) -> 62 | AT32: =IFERROR((SUMPRODUCT(AL32:AR32,{5,4,3,2,1,0.5,0})/(AS32*5))*100,"") -> 27.580645 | AU32: =SUM(AO32:AR32) -> 52 | AV32: =IFERROR(SUMPRODUCT(AL32:AR32,{1,2,3,4,5,6,7})/AS32,"") -> 4.8225806 | AW32: =IF(AV32="","",IF(AV32<=1.4999,"A-EXCELLENT",IF(AV32<=2.4999,"B-VERY GOOD",IF(AV32<=3.4999,"C-GOOD",IF(AV32<=4.4999,"D-AVERAGE",IF(AV32<=5.4999,"E-SATISFACTORY",IF(AV32<=6.4999,"S-SUBSIDIARY",IF(AV32<=7,"F-FAIL","")))))))) -> E-SATISFACTORY
